<?xml version="1.0" ?>
<!-- =================================================================================== -->
<!-- |    This document was autogenerated by xacro from src/exo_description/urdf/exo.xacro | -->
<!-- |    EDITING THIS FILE BY HAND IS NOT RECOMMENDED                                 | -->
<!-- =================================================================================== -->
<robot name="exo">
  <material name="silver">
    <color rgba="0.700 0.700 0.700 1.000"/>
  </material>
  <material name="black">
    <color rgba="0.200 0.200 0.200 1.000"/>
  </material>
  <link name="world"/>
  <joint name="world_fixed" type="fixed">
    <parent link="world"/>
    <child link="base_link"/>
    <origin rpy="0 0 0" xyz="0 0 0.6"/>
  </joint>
  <!-- All modes mount each arm under a shared base_link with prefix-aware mount joints. -->
  <link name="base_link">
    <inertial>
      <origin rpy="0 0 0" xyz="0 0 0"/>
      <mass value="0.001"/>
      <inertia ixx="1e-06" ixy="0" ixz="0" iyy="1e-06" iyz="0" izz="1e-06"/>
    </inertial>
  </link>
  <joint name="left_mount_joint" type="fixed">
    <origin rpy="0 0 0" xyz="0 0.2 0"/>
    <parent link="base_link"/>
    <child link="left_base_link"/>
  </joint>
  <link name="left_base_link">
    <inertial>
      <origin rpy="0 0 0" xyz="-0.06508829102930236 -0.0016392947082375286 -0.029106797642733048"/>
      <mass value="0.071076"/>
      <inertia ixx="0.000253" ixy="-9e-06" ixz="-0.000127" iyy="0.00039" iyz="-4e-06" izz="0.000225"/>
    </inertial>
    <visual>
      <origin rpy="0 0 0" xyz="0 0 0"/>
      <geometry>
        <mesh filename="package://exo_description/meshes/exo_assembly/left/base_link.stl" scale="0.001 0.001 0.001"/>
      </geometry>
      <material name="silver"/>
    </visual>
  </link>
  <link name="left_motor_1">
    <inertial>
      <origin rpy="0 0 0" xyz="-0.028657148535228882 -0.0008037659584219806 0.00012366679922792834"/>
      <mass value="0.3365576984957861"/>
      <inertia ixx="0.000158" ixy="-7e-06" ixz="1e-06" iyy="0.000207" iyz="1e-06" izz="0.000208"/>
    </inertial>
    <visual>
      <origin rpy="0 0 0" xyz="0.094353 -0.00061 0.063136"/>
      <geometry>
        <mesh filename="package://exo_description/meshes/exo_assembly/left/Left_Motor_1_1.stl" scale="0.001 0.001 0.001"/>
      </geometry>
      <material name="silver"/>
    </visual>
  </link>
  <link name="left_component_1">
    <inertial>
      <origin rpy="0 0 0" xyz="0.017291080002229037 0.002735639742798342 0.08182000531860147"/>
      <mass value="0.13580987071810816"/>
      <inertia ixx="0.000224" ixy="4e-06" ixz="-0.000101" iyy="0.000337" iyz="-2e-06" izz="0.000165"/>
    </inertial>
    <visual>
      <origin rpy="0 0 0" xyz="0.097353 -0.00061 0.063136"/>
      <geometry>
        <mesh filename="package://exo_description/meshes/exo_assembly/left/Left_Component_1_1.stl" scale="0.001 0.001 0.001"/>
      </geometry>
      <material name="silver"/>
    </visual>
  </link>
  <link name="left_motor_2">
    <inertial>
      <origin rpy="0 0 0" xyz="9.522009318585489e-05 8.756209107413371e-05 0.025669346895594282"/>
      <mass value="0.3365576984957861"/>
      <inertia ixx="0.000208" ixy="0.0" ixz="-1e-06" iyy="0.000207" iyz="5e-06" izz="0.000158"/>
    </inertial>
    <visual>
      <origin rpy="0 0 0" xyz="0.010353 -0.004345 -0.043799"/>
      <geometry>
        <mesh filename="package://exo_description/meshes/exo_assembly/left/Left_Motor_2_1.stl" scale="0.001 0.001 0.001"/>
      </geometry>
      <material name="silver"/>
    </visual>
  </link>
  <link name="left_component_2">
    <inertial>
      <origin rpy="0 0 0" xyz="0.02130252609513996 -0.06354392139822984 -0.004297968633705511"/>
      <mass value="0.06901401596668413"/>
      <inertia ixx="0.000158" ixy="5e-05" ixz="-2e-06" iyy="2.6e-05" iyz="5e-06" izz="0.000182"/>
    </inertial>
    <visual>
      <origin rpy="0 0 0" xyz="0.010353 -0.00424 -0.040801"/>
      <geometry>
        <mesh filename="package://exo_description/meshes/exo_assembly/left/Left_Component_2_1.stl" scale="0.001 0.001 0.001"/>
      </geometry>
      <material name="silver"/>
    </visual>
  </link>
  <link name="left_component_3">
    <inertial>
      <origin rpy="0 0 0" xyz="0.03615700401627118 -0.08448867239925995 -0.008977979556696391"/>
      <mass value="0.25726311190565365"/>
      <inertia ixx="0.001177" ixy="0.0004" ixz="3.6e-05" iyy="0.000369" iyz="2.1e-05" izz="0.001416"/>
    </inertial>
    <visual>
      <origin rpy="0 0 0" xyz="-0.007995 0.050713 -0.030712"/>
      <geometry>
        <mesh filename="package://exo_description/meshes/exo_assembly/left/Left_Component_3_1.stl" scale="0.001 0.001 0.001"/>
      </geometry>
      <material name="silver"/>
    </visual>
  </link>
  <link name="left_motor_3">
    <inertial>
      <origin rpy="0 0 0" xyz="-0.0002717727838932593 0.00017757175027499628 0.028666777586146615"/>
      <mass value="0.3365576984957861"/>
      <inertia ixx="0.000208" ixy="-0.0" ixz="2e-06" iyy="0.000207" iyz="5e-06" izz="0.000158"/>
    </inertial>
    <visual>
      <origin rpy="0 0 0" xyz="-0.07979 0.264928 -0.040288"/>
      <geometry>
        <mesh filename="package://exo_description/meshes/exo_assembly/left/Left_Motor_3_1.stl" scale="0.001 0.001 0.001"/>
      </geometry>
      <material name="silver"/>
    </visual>
  </link>
  <link name="left_component_4">
    <inertial>
      <origin rpy="0 0 0" xyz="-0.08439620971621951 0.0033097944704012505 -0.008999385990610932"/>
      <mass value="0.07092471532695957"/>
      <inertia ixx="4.2e-05" ixy="1.3e-05" ixz="-2.2e-05" iyy="0.000201" iyz="-1e-05" izz="0.000218"/>
    </inertial>
    <visual>
      <origin rpy="0 0 0" xyz="-0.079795 0.264831 -0.043287"/>
      <geometry>
        <mesh filename="package://exo_description/meshes/exo_assembly/left/Left_Component_4_1.stl" scale="0.001 0.001 0.001"/>
      </geometry>
      <material name="silver"/>
    </visual>
  </link>
  <joint name="left_revolute_1" type="revolute">
    <origin rpy="0 0 0" xyz="-0.094353 0.00061 -0.063136"/>
    <parent link="left_base_link"/>
    <child link="left_motor_1"/>
    <axis xyz="1.0 0.0 0.0"/>
    <limit effort="20" lower="-3.14" upper="0" velocity="11"/>
  </joint>
  <joint name="left_fixed_1" type="fixed">
    <origin rpy="0 0 0" xyz="-0.003 0.0 0.0"/>
    <parent link="left_motor_1"/>
    <child link="left_component_1"/>
  </joint>
  <joint name="left_fixed_2" type="fixed">
    <origin rpy="0 0 0" xyz="0.087 0.003735 0.106935"/>
    <parent link="left_component_1"/>
    <child link="left_motor_2"/>
  </joint>
  <joint name="left_revolute_2" type="revolute">
    <origin rpy="0 0 0" xyz="0.0 -0.000105 -0.002998"/>
    <parent link="left_motor_2"/>
    <child link="left_component_2"/>
    <axis xyz="0.0 -0.034899 -0.999391"/>
    <limit effort="20" lower="-3.3" upper="0" velocity="11"/>
  </joint>
  <joint name="left_fixed_3" type="fixed">
    <origin rpy="0 0 0" xyz="0.018348 -0.054953 -0.010089"/>
    <parent link="left_component_2"/>
    <child link="left_component_3"/>
  </joint>
  <joint name="left_revolute_3" type="revolute">
    <origin rpy="0 0 0" xyz="0.071795 -0.214215 0.009576"/>
    <parent link="left_component_3"/>
    <child link="left_motor_3"/>
    <axis xyz="-0.001694 -0.032292 -0.999477"/>
    <limit effort="20" lower="-2.08" upper="0" velocity="11"/>
  </joint>
  <joint name="left_fixed_4" type="fixed">
    <origin rpy="0 0 0" xyz="5e-06 9.7e-05 0.002999"/>
    <parent link="left_motor_3"/>
    <child link="left_component_4"/>
  </joint>
  <ros2_control name="exo_system" type="system">
    <hardware>
      <plugin>exo_hardware/teensy_plugin</plugin>
      <param name="effort_stiction_comp_enabled">false</param>
      <param name="motor_ids">4,5,6</param>
      <param name="joint_directions">-1,1,-1</param>
      <param name="effort_stiction_tau_values">0.65,0.86,1.26</param>
      <param name="effort_stiction_slope_values">1, 1, 1</param>
    </hardware>
    <joint name="left_revolute_1">
      <command_interface name="effort"/>
      <state_interface name="position">
        <param name="initial_value">-1.53</param>
      </state_interface>
      <state_interface name="velocity"/>
      <state_interface name="effort"/>
    </joint>
    <joint name="left_revolute_2">
      <command_interface name="effort"/>
      <state_interface name="position">
        <param name="initial_value">-2.82</param>
      </state_interface>
      <state_interface name="velocity"/>
      <state_interface name="effort"/>
    </joint>
    <joint name="left_revolute_3">
      <command_interface name="effort"/>
      <state_interface name="position">
        <param name="initial_value">-2.00</param>
      </state_interface>
      <state_interface name="velocity"/>
      <state_interface name="effort"/>
    </joint>
  </ros2_control>
</robot>
