<?xml version="1.0" ?>
<!-- =================================================================================== -->
<!-- |    This document was autogenerated by xacro from src/exo_description/urdf/exo.xacro | -->
<!-- |    EDITING THIS FILE BY HAND IS NOT RECOMMENDED                                 | -->
<!-- =================================================================================== -->
<robot name="exo">
  <material name="silver">
    <color rgba="0.700 0.700 0.700 1.000"/>
  </material>
  <material name="black">
    <color rgba="0.200 0.200 0.200 1.000"/>
  </material>
  <link name="world"/>
  <joint name="world_fixed" type="fixed">
    <parent link="world"/>
    <child link="base_link"/>
    <origin rpy="0 0 0" xyz="0 0 0.6"/>
  </joint>
  <!-- All modes mount each arm under a shared base_link with prefix-aware mount joints. -->
  <link name="base_link">
    <inertial>
      <origin rpy="0 0 0" xyz="0 0 0"/>
      <mass value="0.001"/>
      <inertia ixx="1e-06" ixy="0" ixz="0" iyy="1e-06" iyz="0" izz="1e-06"/>
    </inertial>
  </link>
  <joint name="right_mount_joint" type="fixed">
    <origin rpy="0 0 0" xyz="0 -0.2 0"/>
    <parent link="base_link"/>
    <child link="right_base_link"/>
  </joint>
  <link name="right_base_link">
    <inertial>
      <origin rpy="0 0 0" xyz="-0.06508828909321891 0.0016392932839860918 -0.029106794021422928"/>
      <mass value="0.071076"/>
      <inertia ixx="0.000208" ixy="8e-06" ixz="-0.000104" iyy="0.00032" iyz="3e-06" izz="0.000185"/>
    </inertial>
    <visual>
      <origin rpy="0 0 0" xyz="0 0 0"/>
      <geometry>
        <mesh filename="package://exo_description/meshes/exo_assembly/right/base_link.stl" scale="0.001 0.001 0.001"/>
      </geometry>
      <material name="silver"/>
    </visual>
  </link>
  <link name="right_component_1">
    <inertial>
      <origin rpy="0 0 0" xyz="0.020078156586478324 -0.002520887276899919 0.07676564491860602"/>
      <mass value="0.10340048966459635"/>
      <inertia ixx="0.000203" ixy="-4e-06" ixz="-0.0001" iyy="0.000303" iyz="1e-06" izz="0.000152"/>
    </inertial>
    <visual>
      <origin rpy="0 0 0" xyz="0.097353 0.00061 0.063136"/>
      <geometry>
        <mesh filename="package://exo_description/meshes/exo_assembly/right/Right_Component_1_1.stl" scale="0.001 0.001 0.001"/>
      </geometry>
      <material name="silver"/>
    </visual>
  </link>
  <link name="right_motor_1">
    <inertial>
      <origin rpy="0 0 0" xyz="-0.028657146735079228 -0.0008124469950160578 5.2337020642223564e-05"/>
      <mass value="0.33655768070512676"/>
      <inertia ixx="0.000158" ixy="-7e-06" ixz="0.0" iyy="0.000206" iyz="-0.0" izz="0.000208"/>
    </inertial>
    <visual>
      <origin rpy="0 0 0" xyz="0.094353 0.00061 0.063136"/>
      <geometry>
        <mesh filename="package://exo_description/meshes/exo_assembly/right/Right_Motor_1_1.stl" scale="0.001 0.001 0.001"/>
      </geometry>
      <material name="silver"/>
    </visual>
  </link>
  <link name="right_motor_2">
    <inertial>
      <origin rpy="0 0 0" xyz="0.0008094200168279157 -0.0008145820388575867 0.02564395698733552"/>
      <mass value="0.33655768070512676"/>
      <inertia ixx="0.000206" ixy="0.0" ixz="-7e-06" iyy="0.000208" iyz="1e-06" izz="0.000158"/>
    </inertial>
    <visual>
      <origin rpy="0 0 0" xyz="0.010353 0.004345 -0.043799"/>
      <geometry>
        <mesh filename="package://exo_description/meshes/exo_assembly/right/Right_Motor_2_1.stl" scale="0.001 0.001 0.001"/>
      </geometry>
      <material name="silver"/>
    </visual>
  </link>
  <link name="right_component_2">
    <inertial>
      <origin rpy="0 0 0" xyz="0.02170967506266145 0.06340564193577251 -0.004302798150324916"/>
      <mass value="0.06901401423488361"/>
      <inertia ixx="0.000157" ixy="-5.1e-05" ixz="-2e-06" iyy="2.6e-05" iyz="-5e-06" izz="0.000182"/>
    </inertial>
    <visual>
      <origin rpy="0 0 0" xyz="0.010353 0.00424 -0.040801"/>
      <geometry>
        <mesh filename="package://exo_description/meshes/exo_assembly/right/Right_Component_2_1.stl" scale="0.001 0.001 0.001"/>
      </geometry>
      <material name="silver"/>
    </visual>
  </link>
  <link name="right_component_3">
    <inertial>
      <origin rpy="0 0 0" xyz="0.0362007475571462 0.08488733536574525 -0.02097339196773956"/>
      <mass value="0.2572924347231441"/>
      <inertia ixx="0.001177" ixy="-0.0004" ixz="3.6e-05" iyy="0.00037" iyz="-2.1e-05" izz="0.001416"/>
    </inertial>
    <visual>
      <origin rpy="0 0 0" xyz="-0.008346 -0.050211 -0.041702"/>
      <geometry>
        <mesh filename="package://exo_description/meshes/exo_assembly/right/Right_Component_3_1.stl" scale="0.001 0.001 0.001"/>
      </geometry>
      <material name="silver"/>
    </visual>
  </link>
  <link name="right_motor_3">
    <inertial>
      <origin rpy="0 0 0" xyz="0.00071319645679499 -0.0004566132738064721 0.028656360017304303"/>
      <mass value="0.33655768070512676"/>
      <inertia ixx="0.000207" ixy="-0.0" ixz="-6e-06" iyy="0.000208" iyz="-2e-06" izz="0.000158"/>
    </inertial>
    <visual>
      <origin rpy="0 0 0" xyz="-0.080242 -0.26481 -0.039283"/>
      <geometry>
        <mesh filename="package://exo_description/meshes/exo_assembly/right/Right_Motor_3_1.stl" scale="0.001 0.001 0.001"/>
      </geometry>
      <material name="silver"/>
    </visual>
  </link>
  <link name="right_component_4">
    <inertial>
      <origin rpy="0 0 0" xyz="-0.08441969431975782 -0.002715032580566934 -0.008979759026676165"/>
      <mass value="0.07092471532503089"/>
      <inertia ixx="4.2e-05" ixy="-1.2e-05" ixz="-2.2e-05" iyy="0.000201" iyz="1e-05" izz="0.000218"/>
    </inertial>
    <visual>
      <origin rpy="0 0 0" xyz="-0.080247 -0.264713 -0.042282"/>
      <geometry>
        <mesh filename="package://exo_description/meshes/exo_assembly/right/Right_Component_4_1.stl" scale="0.001 0.001 0.001"/>
      </geometry>
      <material name="silver"/>
    </visual>
  </link>
  <joint name="right_fixed_1" type="fixed">
    <origin rpy="0 0 0" xyz="-0.003 0.0 0.0"/>
    <parent link="right_motor_1"/>
    <child link="right_component_1"/>
  </joint>
  <joint name="right_revolute_1" type="revolute">
    <origin rpy="0 0 0" xyz="-0.094353 -0.00061 -0.063136"/>
    <parent link="right_base_link"/>
    <child link="right_motor_1"/>
    <axis xyz="-1.0 -0.0 0.0"/>
    <limit effort="20" lower="-3.14" upper="0" velocity="11"/>
  </joint>
  <joint name="right_fixed_2" type="fixed">
    <origin rpy="0 0 0" xyz="0.087 -0.003735 0.106935"/>
    <parent link="right_component_1"/>
    <child link="right_motor_2"/>
  </joint>
  <joint name="right_revolute_2" type="revolute">
    <origin rpy="0 0 0" xyz="0.0 0.000105 -0.002998"/>
    <parent link="right_motor_2"/>
    <child link="right_component_2"/>
    <axis xyz="0.0 -0.034899 0.999391"/>
    <limit effort="20" lower="-3.3" upper="0" velocity="11"/>
  </joint>
  <joint name="right_fixed_3" type="fixed">
    <origin rpy="0 0 0" xyz="0.018699 0.054451 0.000901"/>
    <parent link="right_component_2"/>
    <child link="right_component_3"/>
  </joint>
  <joint name="right_revolute_3" type="revolute">
    <origin rpy="0 0 0" xyz="0.071896 0.214599 -0.002419"/>
    <parent link="right_component_3"/>
    <child link="right_motor_3"/>
    <axis xyz="0.001695 -0.032293 0.999477"/>
    <limit effort="20" lower="-2.08" upper="0" velocity="11"/>
  </joint>
  <joint name="right_fixed_4" type="fixed">
    <origin rpy="0 0 0" xyz="5e-06 -9.7e-05 0.002999"/>
    <parent link="right_motor_3"/>
    <child link="right_component_4"/>
  </joint>
  <ros2_control name="exo_system" type="system">
    <hardware>
      <plugin>exo_hardware/teensy_plugin</plugin>
      <param name="effort_stiction_comp_enabled">false</param>
      <param name="effort_stiction_tau_values">0.65,0.86,1.26</param>
      <param name="effort_stiction_slope_values">1, 1, 1</param>
    </hardware>
    <joint name="right_revolute_1">
      <command_interface name="effort"/>
      <state_interface name="position">
        <param name="initial_value">-1.53</param>
      </state_interface>
      <state_interface name="velocity"/>
      <state_interface name="effort"/>
    </joint>
    <joint name="right_revolute_2">
      <command_interface name="effort"/>
      <state_interface name="position">
        <param name="initial_value">-2.82</param>
      </state_interface>
      <state_interface name="velocity"/>
      <state_interface name="effort"/>
    </joint>
    <joint name="right_revolute_3">
      <command_interface name="effort"/>
      <state_interface name="position">
        <param name="initial_value">-2.00</param>
      </state_interface>
      <state_interface name="velocity"/>
      <state_interface name="effort"/>
    </joint>
  </ros2_control>
</robot>
