<?xml version="1.0" ?>
<!-- =================================================================================== -->
<!-- |    This document was autogenerated by xacro from /home/farid/tesis/exo_right_arm_ws/build/exo_description/exo_build.xacro | -->
<!-- |    EDITING THIS FILE BY HAND IS NOT RECOMMENDED                                 | -->
<!-- =================================================================================== -->
<robot name="exo">
  <material name="silver">
    <color rgba="0.700 0.700 0.700 1.000"/>
  </material>
  <material name="black">
    <color rgba="0.200 0.200 0.200 1.000"/>
  </material>
  <transmission name="revolute_1_tran">
    <type>transmission_interface/SimpleTransmission</type>
    <joint name="revolute_1">
      <hardwareInterface>hardware_interface/EffortJointInterface</hardwareInterface>
    </joint>
    <actuator name="revolute_1_actr">
      <hardwareInterface>hardware_interface/EffortJointInterface</hardwareInterface>
      <mechanicalReduction>1</mechanicalReduction>
    </actuator>
  </transmission>
  <transmission name="revolute_5_tran">
    <type>transmission_interface/SimpleTransmission</type>
    <joint name="revolute_5">
      <hardwareInterface>hardware_interface/EffortJointInterface</hardwareInterface>
    </joint>
    <actuator name="revolute_5_actr">
      <hardwareInterface>hardware_interface/EffortJointInterface</hardwareInterface>
      <mechanicalReduction>1</mechanicalReduction>
    </actuator>
  </transmission>
  <transmission name="revolute_7_tran">
    <type>transmission_interface/SimpleTransmission</type>
    <joint name="revolute_7">
      <hardwareInterface>hardware_interface/EffortJointInterface</hardwareInterface>
    </joint>
    <actuator name="revolute_7_actr">
      <hardwareInterface>hardware_interface/EffortJointInterface</hardwareInterface>
      <mechanicalReduction>1</mechanicalReduction>
    </actuator>
  </transmission>
  <link name="world"/>
  <joint name="world_fixed" type="fixed">
    <parent link="world"/>
    <child link="base_link"/>
    <origin rpy="0 0 0" xyz="0 0 0.6"/>
  </joint>
  <link name="base_link">
    <inertial>
      <origin rpy="0 0 0" xyz="0.012748850487473646 0.0012395946054243722 0.013826907905998666"/>
      <mass value="0.07388024509698206"/>
      <inertia ixx="8e-05" ixy="2e-06" ixz="-5.1e-05" iyy="0.000154" iyz="-1e-05" izz="0.000109"/>
    </inertial>
    <visual>
      <origin rpy="0 0 0" xyz="0 0 0"/>
      <geometry>
        <mesh filename="package://exo_description/meshes/base_link.stl" scale="0.001 0.001 0.001"/>
      </geometry>
      <material name="silver"/>
    </visual>
    <collision>
      <origin rpy="0 0 0" xyz="0 0 0"/>
      <geometry>
        <mesh filename="package://exo_description/meshes/base_link.stl" scale="0.001 0.001 0.001"/>
      </geometry>
    </collision>
  </link>
  <link name="Motor1_1">
    <inertial>
      <origin rpy="0 0 0" xyz="-0.02865689684955547 0.0008019947900518482 -0.00013732170892716988"/>
      <mass value="0.33655764736226634"/>
      <inertia ixx="0.000158" ixy="7e-06" ixz="-1e-06" iyy="0.000206" iyz="-0.0" izz="0.000208"/>
    </inertial>
    <visual>
      <origin rpy="0 0 0" xyz="0.014 0.0 -0.0"/>
      <geometry>
        <mesh filename="package://exo_description/meshes/Motor1_1.stl" scale="0.001 0.001 0.001"/>
      </geometry>
      <material name="black"/>
    </visual>
    <collision>
      <origin rpy="0 0 0" xyz="0.014 0.0 -0.0"/>
      <geometry>
        <mesh filename="package://exo_description/meshes/Motor1_1.stl" scale="0.001 0.001 0.001"/>
      </geometry>
    </collision>
  </link>
  <link name="Componente2_v1_1">
    <inertial>
      <origin rpy="0 0 0" xyz="0.025697121565106763 -0.06800197164371612 0.0006322543327434366"/>
      <mass value="0.0856142757419247"/>
      <inertia ixx="0.000127" ixy="6.9e-05" ixz="-6e-06" iyy="0.000133" iyz="1e-06" izz="0.000214"/>
    </inertial>
    <visual>
      <origin rpy="0 0 0" xyz="0.017 0.0 -0.0"/>
      <geometry>
        <mesh filename="package://exo_description/meshes/Componente2_v1_1.stl" scale="0.001 0.001 0.001"/>
      </geometry>
      <material name="silver"/>
    </visual>
    <collision>
      <origin rpy="0 0 0" xyz="0.017 0.0 -0.0"/>
      <geometry>
        <mesh filename="package://exo_description/meshes/Componente2_v1_1.stl" scale="0.001 0.001 0.001"/>
      </geometry>
    </collision>
  </link>
  <link name="Motor2_1">
    <inertial>
      <origin rpy="0 0 0" xyz="0.0008019947900903546 -0.025656896849592187 0.00013732170895816803"/>
      <mass value="0.33655764736226634"/>
      <inertia ixx="0.000206" ixy="7e-06" ixz="0.0" iyy="0.000158" iyz="1e-06" izz="0.000208"/>
    </inertial>
    <visual>
      <origin rpy="0 0 0" xyz="-0.07 0.087 -0.0"/>
      <geometry>
        <mesh filename="package://exo_description/meshes/Motor2_1.stl" scale="0.001 0.001 0.001"/>
      </geometry>
      <material name="black"/>
    </visual>
    <collision>
      <origin rpy="0 0 0" xyz="-0.07 0.087 -0.0"/>
      <geometry>
        <mesh filename="package://exo_description/meshes/Motor2_1.stl" scale="0.001 0.001 0.001"/>
      </geometry>
    </collision>
  </link>
  <link name="Componente3_v1_1">
    <inertial>
      <origin rpy="0 0 0" xyz="0.00032953390008541583 0.004560809428740015 -0.04548170531617862"/>
      <mass value="0.02436487236137751"/>
      <inertia ixx="4.5e-05" ixy="-0.0" ixz="0.0" iyy="4.7e-05" iyz="0.0" izz="3e-06"/>
    </inertial>
    <visual>
      <origin rpy="0 0 0" xyz="-0.07 0.084 -0.0"/>
      <geometry>
        <mesh filename="package://exo_description/meshes/Componente3_v1_1.stl" scale="0.001 0.001 0.001"/>
      </geometry>
      <material name="silver"/>
    </visual>
    <collision>
      <origin rpy="0 0 0" xyz="-0.07 0.084 -0.0"/>
      <geometry>
        <mesh filename="package://exo_description/meshes/Componente3_v1_1.stl" scale="0.001 0.001 0.001"/>
      </geometry>
    </collision>
  </link>
  <link name="Componente4_v1_1">
    <inertial>
      <origin rpy="0 0 0" xyz="-0.010220970902704345 0.012182176440413015 -0.11338415880449806"/>
      <mass value="0.16326913907635673"/>
      <inertia ixx="0.000882" ixy="3.1e-05" ixz="-3.5e-05" iyy="0.000951" iyz="-4.9e-05" izz="0.000135"/>
    </inertial>
    <visual>
      <origin rpy="0 0 0" xyz="-0.07033 0.081 0.045569"/>
      <geometry>
        <mesh filename="package://exo_description/meshes/Componente4_v1_1.stl" scale="0.001 0.001 0.001"/>
      </geometry>
      <material name="silver"/>
    </visual>
    <collision>
      <origin rpy="0 0 0" xyz="-0.07033 0.081 0.045569"/>
      <geometry>
        <mesh filename="package://exo_description/meshes/Componente4_v1_1.stl" scale="0.001 0.001 0.001"/>
      </geometry>
    </collision>
  </link>
  <link name="Motor3_1">
    <inertial>
      <origin rpy="0 0 0" xyz="0.0005883974851695895 -0.028656896849589955 0.0005618260705803624"/>
      <mass value="0.33655764736226634"/>
      <inertia ixx="0.000207" ixy="5e-06" ixz="-1e-06" iyy="0.000158" iyz="5e-06" izz="0.000208"/>
    </inertial>
    <visual>
      <origin rpy="0 0 0" xyz="-0.072983 0.0905 0.285589"/>
      <geometry>
        <mesh filename="package://exo_description/meshes/Motor3_1.stl" scale="0.001 0.001 0.001"/>
      </geometry>
      <material name="black"/>
    </visual>
    <collision>
      <origin rpy="0 0 0" xyz="-0.072983 0.0905 0.285589"/>
      <geometry>
        <mesh filename="package://exo_description/meshes/Motor3_1.stl" scale="0.001 0.001 0.001"/>
      </geometry>
    </collision>
  </link>
  <link name="Componente5_v1_1">
    <inertial>
      <origin rpy="0 0 0" xyz="-0.012433445660119731 0.009030253916196301 -0.08353720706436124"/>
      <mass value="0.07092422473137162"/>
      <inertia ixx="0.000201" ixy="1.4e-05" ixz="-1.7e-05" iyy="0.000217" iyz="1.9e-05" izz="4.3e-05"/>
    </inertial>
    <visual>
      <origin rpy="0 0 0" xyz="-0.072983 0.0935 0.285589"/>
      <geometry>
        <mesh filename="package://exo_description/meshes/Componente5_v1_1.stl" scale="0.001 0.001 0.001"/>
      </geometry>
      <material name="silver"/>
    </visual>
    <collision>
      <origin rpy="0 0 0" xyz="-0.072983 0.0935 0.285589"/>
      <geometry>
        <mesh filename="package://exo_description/meshes/Componente5_v1_1.stl" scale="0.001 0.001 0.001"/>
      </geometry>
    </collision>
  </link>
  <joint name="revolute_1" type="revolute">
    <origin rpy="0 0 0" xyz="-0.014 0.0 0.0"/>
    <parent link="base_link"/>
    <child link="Motor1_1"/>
    <axis xyz="-1.0 -0.0 0.0"/>
    <dynamics damping="0.012" friction="0.1184"/>
    <limit effort="20" lower="0" upper="1.919" velocity="11"/>
  </joint>
  <joint name="rigid_2" type="fixed">
    <origin rpy="0 0 0" xyz="-0.003 0.0 0.0"/>
    <parent link="Motor1_1"/>
    <child link="Componente2_v1_1"/>
  </joint>
  <joint name="rigid_3" type="fixed">
    <origin rpy="0 0 0" xyz="0.087 -0.087 0.0"/>
    <parent link="Componente2_v1_1"/>
    <child link="Motor2_1"/>
  </joint>
  <joint name="revolute_2" type="revolute">
    <origin rpy="0 0 0" xyz="0.0 0.003 0.0"/>
    <parent link="Motor2_1"/>
    <child link="Componente3_v1_1"/>
    <axis xyz="0.0 -1.0 0.0"/>
    <dynamics damping="0.012" friction="0.1184"/>
    <limit effort="20" lower="-0.56" upper="2.793" velocity="11"/>
  </joint>
  <joint name="rigid_6" type="fixed">
    <origin rpy="0 0 0" xyz="0.00033 0.003 -0.045569"/>
    <parent link="Componente3_v1_1"/>
    <child link="Componente4_v1_1"/>
  </joint>
  <joint name="revolute_3" type="revolute">
    <origin rpy="0 0 0" xyz="0.002653 -0.0095 -0.24002"/>
    <parent link="Componente4_v1_1"/>
    <child link="Motor3_1"/>
    <axis xyz="-0.0 -1.0 -0.0"/>
    <dynamics damping="0.012" friction="0.1184"/>
    <limit effort="20" lower="0" upper="2.094" velocity="11"/>
  </joint>
  <joint name="rigid_8" type="fixed">
    <origin rpy="0 0 0" xyz="0.0 -0.003 0.0"/>
    <parent link="Motor3_1"/>
    <child link="Componente5_v1_1"/>
  </joint>
  <ros2_control name="exo_right_arm" type="system">
    <hardware>
      <plugin>exo_hardware/teensy_plugin</plugin>
    </hardware>
    <joint name="revolute_1">
      <command_interface name="effort"/>
      <state_interface name="position"/>
      <state_interface name="velocity"/>
      <state_interface name="effort"/>
    </joint>
    <joint name="revolute_2">
      <command_interface name="effort"/>
      <state_interface name="position"/>
      <state_interface name="velocity"/>
      <state_interface name="effort"/>
    </joint>
    <joint name="revolute_3">
      <command_interface name="effort"/>
      <state_interface name="position"/>
      <state_interface name="velocity"/>
      <state_interface name="effort"/>
    </joint>
  </ros2_control>
</robot>
